Workbook

Sheet Tổng hợp
A1: Flow / Step ID | B1: Tên bước | C1: Áp dụng cho luồng | D1: Tổng TC | E1: Critical/Highest | F1: High | G1: Done | H1: % Done
A2: HF-01 | B2: Happy – E2E | C2: Kiểm tra luồng | D2: =COUNTIF(Mapping!$C$2:$C$750,A2) | E2: =COUNTIFS(Mapping!$C$2:$C$750,A2,Mapping!$O$2:$O$750,"Critical")+COUNTIFS(Mapping!$C$2:$C$750,A2,Mapping!$O$2:$O$750,"Highest") | F2: =COUNTIFS(Mapping!$C$2:$C$750,A2,Mapping!$O$2:$O$750,"High") | G2: =COUNTIFS(Mapping!$C$2:$C$750,A2,Mapping!$S$2:$S$750,"Done") | H2: =IF(D2=0,0,G2/D2)
A3: HF-02 | B3: Happy – E2E | C3: Kiểm tra luồng | D3: =COUNTIF(Mapping!$C$2:$C$750,A3) | E3: =COUNTIFS(Mapping!$C$2:$C$750,A3,Mapping!$O$2:$O$750,"Critical")+COUNTIFS(Mapping!$C$2:$C$750,A3,Mapping!$O$2:$O$750,"Highest") | F3: =COUNTIFS(Mapping!$C$2:$C$750,A3,Mapping!$O$2:$O$750,"High") | G3: =COUNTIFS(Mapping!$C$2:$C$750,A3,Mapping!$S$2:$S$750,"Done") | H3: =IF(D3=0,0,G3/D3)
A4: HF-03 | B4: Happy – E2E | C4: Kiểm tra luồng | D4: =COUNTIF(Mapping!$C$2:$C$750,A4) | E4: =COUNTIFS(Mapping!$C$2:$C$750,A4,Mapping!$O$2:$O$750,"Critical")+COUNTIFS(Mapping!$C$2:$C$750,A4,Mapping!$O$2:$O$750,"Highest") | F4: =COUNTIFS(Mapping!$C$2:$C$750,A4,Mapping!$O$2:$O$750,"High") | G4: =COUNTIFS(Mapping!$C$2:$C$750,A4,Mapping!$S$2:$S$750,"Done") | H4: =IF(D4=0,0,G4/D4)
A5: NE | B5: Negative – E2E | C5: Kiểm tra luồng | D5: =COUNTIF(Mapping!$C$2:$C$750,A5) | E5: =COUNTIFS(Mapping!$C$2:$C$750,A5,Mapping!$O$2:$O$750,"Critical")+COUNTIFS(Mapping!$C$2:$C$750,A5,Mapping!$O$2:$O$750,"Highest") | F5: =COUNTIFS(Mapping!$C$2:$C$750,A5,Mapping!$O$2:$O$750,"High") | G5: =COUNTIFS(Mapping!$C$2:$C$750,A5,Mapping!$S$2:$S$750,"Done") | H5: =IF(D5=0,0,G5/D5)
A6: S01 | B6: Danh sách & tìm kiếm giao dịch | C6: HF-01/02/03 | D6: =COUNTIF(Mapping!$C$2:$C$750,A6) | E6: =COUNTIFS(Mapping!$C$2:$C$750,A6,Mapping!$O$2:$O$750,"Critical")+COUNTIFS(Mapping!$C$2:$C$750,A6,Mapping!$O$2:$O$750,"Highest") | F6: =COUNTIFS(Mapping!$C$2:$C$750,A6,Mapping!$O$2:$O$750,"High") | G6: =COUNTIFS(Mapping!$C$2:$C$750,A6,Mapping!$S$2:$S$750,"Done") | H6: =IF(D6=0,0,G6/D6)
A7: S02 | B7: Thêm mới – quyền truy cập, điều hướng wizard, tích hợp CIF/GLIMS/Core, hạn mức ngày, Gửi duyệt/Lưu nháp | C7: HF-01/02/03 | D7: =COUNTIF(Mapping!$C$2:$C$750,A7) | E7: =COUNTIFS(Mapping!$C$2:$C$750,A7,Mapping!$O$2:$O$750,"Critical")+COUNTIFS(Mapping!$C$2:$C$750,A7,Mapping!$O$2:$O$750,"Highest") | F7: =COUNTIFS(Mapping!$C$2:$C$750,A7,Mapping!$O$2:$O$750,"High") | G7: =COUNTIFS(Mapping!$C$2:$C$750,A7,Mapping!$S$2:$S$750,"Done") | H7: =IF(D7=0,0,G7/D7)
A8: S03 | B8: Thêm mới – rule chung các trường (khoảng trắng, bắt buộc, độ dài, mặc định) | C8: HF-01/02/03 | D8: =COUNTIF(Mapping!$C$2:$C$750,A8) | E8: =COUNTIFS(Mapping!$C$2:$C$750,A8,Mapping!$O$2:$O$750,"Critical")+COUNTIFS(Mapping!$C$2:$C$750,A8,Mapping!$O$2:$O$750,"Highest") | F8: =COUNTIFS(Mapping!$C$2:$C$750,A8,Mapping!$O$2:$O$750,"High") | G8: =COUNTIFS(Mapping!$C$2:$C$750,A8,Mapping!$S$2:$S$750,"Done") | H8: =IF(D8=0,0,G8/D8)
A9: S04 | B9: Thêm mới – Thông tin khách hàng | C9: HF-01/02/03 | D9: =COUNTIF(Mapping!$C$2:$C$750,A9) | E9: =COUNTIFS(Mapping!$C$2:$C$750,A9,Mapping!$O$2:$O$750,"Critical")+COUNTIFS(Mapping!$C$2:$C$750,A9,Mapping!$O$2:$O$750,"Highest") | F9: =COUNTIFS(Mapping!$C$2:$C$750,A9,Mapping!$O$2:$O$750,"High") | G9: =COUNTIFS(Mapping!$C$2:$C$750,A9,Mapping!$S$2:$S$750,"Done") | H9: =IF(D9=0,0,G9/D9)
A10: S05 | B10: Thêm mới – Thông tin LC: loại LC, BIC, ngày, ngân hàng, bên phát hành, người hưởng | C10: HF-01/02/03 | D10: =COUNTIF(Mapping!$C$2:$C$750,A10) | E10: =COUNTIFS(Mapping!$C$2:$C$750,A10,Mapping!$O$2:$O$750,"Critical")+COUNTIFS(Mapping!$C$2:$C$750,A10,Mapping!$O$2:$O$750,"Highest") | F10: =COUNTIFS(Mapping!$C$2:$C$750,A10,Mapping!$O$2:$O$750,"High") | G10: =COUNTIFS(Mapping!$C$2:$C$750,A10,Mapping!$S$2:$S$750,"Done") | H10: =IF(D10=0,0,G10/D10)
A11: S06 | B11: Thêm mới – Giá trị LC, dung sai, nơi có giá trị | C11: HF-01/02/03 | D11: =COUNTIF(Mapping!$C$2:$C$750,A11) | E11: =COUNTIFS(Mapping!$C$2:$C$750,A11,Mapping!$O$2:$O$750,"Critical")+COUNTIFS(Mapping!$C$2:$C$750,A11,Mapping!$O$2:$O$750,"Highest") | F11: =COUNTIFS(Mapping!$C$2:$C$750,A11,Mapping!$O$2:$O$750,"High") | G11: =COUNTIFS(Mapping!$C$2:$C$750,A11,Mapping!$S$2:$S$750,"Done") | H11: =IF(D11=0,0,G11/D11)
A12: S07 | B12: Thêm mới – Phương thức thanh toán, hối phiếu, kỳ hạn | C12: HF-01/02/03 | D12: =COUNTIF(Mapping!$C$2:$C$750,A12) | E12: =COUNTIFS(Mapping!$C$2:$C$750,A12,Mapping!$O$2:$O$750,"Critical")+COUNTIFS(Mapping!$C$2:$C$750,A12,Mapping!$O$2:$O$750,"Highest") | F12: =COUNTIFS(Mapping!$C$2:$C$750,A12,Mapping!$O$2:$O$750,"High") | G12: =COUNTIFS(Mapping!$C$2:$C$750,A12,Mapping!$S$2:$S$750,"Done") | H12: =IF(D12=0,0,G12/D12)
A13: S08 | B13: Thêm mới – Giao hàng & hàng hoá | C13: HF-01/02/03 | D13: =COUNTIF(Mapping!$C$2:$C$750,A13) | E13: =COUNTIFS(Mapping!$C$2:$C$750,A13,Mapping!$O$2:$O$750,"Critical")+COUNTIFS(Mapping!$C$2:$C$750,A13,Mapping!$O$2:$O$750,"Highest") | F13: =COUNTIFS(Mapping!$C$2:$C$750,A13,Mapping!$O$2:$O$750,"High") | G13: =COUNTIFS(Mapping!$C$2:$C$750,A13,Mapping!$S$2:$S$750,"Done") | H13: =IF(D13=0,0,G13/D13)
... A33: P02 | B33: Dialog – Nhập thông tin hồ sơ hậu kiểm | C33: Sau phát hành (cần BO phát hành xong) | D33: =COUNTIF(Mapping!$C$2:$C$750,A33) | E33: =COUNTIFS(Mapping!$C$2:$C$750,A33,Mapping!$O$2:$O$750,"Critical")+COUNTIFS(Mapping!$C$2:$C$750,A33,Mapping!$O$2:$O$750,"Highest") | F33: =COUNTIFS(Mapping!$C$2:$C$750,A33,Mapping!$O$2:$O$750,"High") | G33: =COUNTIFS(Mapping!$C$2:$C$750,A33,Mapping!$S$2:$S$750,"Done") | H33: =IF(D33=0,0,G33/D33)
A34: TOTAL | D34: =SUM(D2:D33) | E34: =SUM(E2:E33) | F34: =SUM(F2:F33) | G34: =SUM(G2:G33) | H34: =IF(D34=0,0,G34/D34)

Sheet Mapping
A1: TC No | B1: Type | C1: Flow / Step ID | D1: Tên bước | E1: Áp dụng cho luồng | F1: Loại | G1: Màn hình (gốc) | H1: Function | I1: Điều kiện 1 | J1: Điều kiện 2 | K1: Summary | L1: Data | M1: Action | N1: Expected Result | O1: Priority | P1: Gợi ý automation | Q1: Automatable? | R1: Katalon Test Case | S1: Trạng thái | T1: Ghi chú | U1: Note (gốc)
A2: 1 | B2: FO-E2E | C2: HF-01 | D2: 1 cấp, không ký số PN | E2: Kiểm tra luồng | F2: Happy – E2E | G2: Tạo đề nghị phát hành | H2: Kiểm tra luồng | I2: Luồng happy case 1 cấp duyệt không ký số pháp nhân | K2: Kiểm tra luồng-Thành công-Tạo đề nghị phát hành-Luồng happy case 1 cấp duyệt không ký số pháp nhân-- | L2: 1 Marker 1 Kế toán trưởng 1 Chủ tài khoản | M2: Step: 1.User Maker login hệ thống FO. 2.Thêm mới 1 bản ghi phát hành LC, nhập liệu các trường thông tin bắt buộc (cấu hình 1 cấp duyệt 2FA, không ký số pháp nhân). 3.Maker thực hiện đẩy giao dịch lên cấp duyệt → bản ghi chuyển "Chờ duyệt". 4.User Kế toán trưởng login hệ thống FO, thực hiện xác thực 2FA và Phê duyệt. 5.User Chủ tài khoản login hệ thống FO, thực hiện Ký số thành công. 6.Quan sát kết quả. | N2: 1.Maker khởi tạo → Trạng thái: "Chờ duyệt". 2.Kế toán trưởng xác thực 2FA và duyệt xong → Trạng thái: "Chờ duyệt". 3.Chủ tài khoản ký số thành công → Hệ thống hiển thị màn hình thông báo thành công, bản ghi chuyển trạng thái "Đã gửi ngân hàng". | O2: Critical | P2: Cần xác nhận: 2FA/OTP; Cần xác nhận: ký số (USB token/HSM?) | S2: Not started
A3: 2 | B3: FO-E2E | C3: HF-01 | D3: 1 cấp, có ký số PN | E3: Kiểm tra luồng | F3: Happy – E2E | G3: Tạo đề nghị phát hành | H3: Kiểm tra luồng | I3: Luồng happy case 1 cấp duyệt có ký số pháp nhân | K3: Kiểm tra luồng-Thành công-Tạo đề nghị phát hành-Luồng happy case 1 cấp duyệt có ký số pháp nhân-- | L3: 1 Marker 1 Kế toán trưởng 1 Chủ tài khoản 1 Người ký pháp nhân | M3: Step: 1.User Maker login hệ thống FO. 2.Thêm mới 1 bản ghi phát hành LC, nhập liệu đầy đủ (cấu hình 1 cấp duyệt 2FA, có ký số pháp nhân). 3.Maker thực hiện đẩy giao dịch lên cấp duyệt → bản ghi chuyển "Chờ duyệt". 4.User Kế toán trưởng login hệ thống FO, thực hiện xác thực 2FA và Phê duyệt. 5.User Chủ tài khoản login hệ thống FO, thực hiện Ký số thành công → bản ghi chuyển trạng thái "Chờ ký số pháp nhân". 6.User đại diện pháp nhân login hệ thống FO, thực hiện Ký số pháp nhân thành công. 7.Quan sát kết quả. | N3: 1.Maker khởi tạo → Trạng thái: "Chờ duyệt". 2.Kế toán trưởng xác thực 2FA và duyệt xong → Trạng thái: "Chờ duyệt". 3.Chủ tài khoản ký số thành công → Trạng thái: "Chờ ký số pháp nhân". 4.Người đại diện pháp nhân ký số pháp nhân thành công → Hệ thống hiển thị màn hình thông báo thành công, bản ghi chuyển trạng thái "Đã gửi ngân hàng". | O3: Critical | P3: Cần xác nhận: 2FA/OTP; Cần xác nhận: ký số (USB token/HSM?) | S3: Not started
A4: 3 | B4: FO-E2E | C4: HF-01 | D4: 2 cấp, không ký số PN | E4: Kiểm tra luồng | F4: Happy – E2E | G4: Tạo đề nghị phát hành | H4: Kiểm tra luồng | I4: Luồng happy case 2 cấp duyệt không có ký số pháp nhân | K4: Kiểm tra luồng-Thành công-Tạo đề nghị phát hành-Luồng happy case 2 cấp duyệt không có ký số pháp nhân-- | L4: 1 Marker 1 Kế toán trưởng 1 Kế toán phó 1 Chủ tài khoản | M4: Step: 1.User Maker login hệ thống FO, thêm mới bản ghi phát hành LC, nhập liệu đầy đủ (cấu hình 2 cấp duyệt 2FA, không ký số pháp nhân). 2.Maker đẩy giao dịch lên cấp duyệt → bản ghi chuyển trạng thái "Chờ duyệt". 3.User Kế toán phó login, thực hiện xác thực 2FA và Phê duyệt → bản ghi chuyển trạng thái "Chờ duyệt cấp tiếp theo". 4.User Kế toán trưởng login, thực hiện xác thực 2FA và Phê duyệt. 5.User Chủ tài khoản login, thực hiện Ký số thành công. 6.Quan sát kết quả. | N4: 1.Maker khởi tạo → Trạng thái: "Chờ duyệt". 2.Kế toán phó xác thực 2FA và duyệt xong (2FA lần 1) → Trạng thái: "Chờ duyệt cấp tiếp theo". 3.Kế toán trưởng xác thực 2FA và duyệt xong (2FA lần 2) → Trạng thái: "Chờ duyệt cấp tiếp theo". 4.Chủ tài khoản ký số thành công → Hệ thống hiển thị màn hình thông báo thành công, bản ghi chuyển trạng thái "Đã gửi ngân hàng". | O4: Critical | P4: Cần xác nhận: 2FA/OTP; Cần xác nhận: ký số (USB token/HSM?) | S4: Not started
A5: 4 | B5: FO-E2E | C5: HF-01 | D5: 2 cấp, có ký số PN | E5: Kiểm tra luồng | F5: Happy – E2E | G5: Tạo đề nghị phát hành | H5: Kiểm tra luồng | I5: Luồng happy case 2 cấp duyệt có ký số pháp nhân | K5: Kiểm tra luồng-Thành công-Tạo đề nghị phát hành-Luồng happy case 2 cấp duyệt có ký số pháp nhân-- | L5: 1 Marker 1 Kế toán trưởng 1 Kế toán phó 1 Chủ tài khoản 1 Người ký pháp nhân | M5: Step: 1.User Maker login hệ thống FO, thêm mới bản ghi phát hành LC, nhập liệu đầy đủ (cấu hình 2 cấp duyệt 2FA, có ký số pháp nhân). 2.Maker đẩy giao dịch lên cấp duyệt → bản ghi chuyển trạng thái "Chờ duyệt". 3.User Kế toán phó login, thực hiện xác thực 2FA và Phê duyệt → bản ghi chuyển trạng thái "Chờ duyệt cấp tiếp theo". 4.User Kế toán trưởng login, thực hiện xác thực 2FA và Phê duyệt. 5.User Chủ tài khoản login, thực hiện Ký số thành công → bản ghi chuyển trạng thái "Chờ ký số pháp nhân". 6.Người dùng có thẩm quyền Ký số pháp nhân login, thực hiện ký số pháp nhân thành công. 7.Quan sát kết quả. | N5: 1.Maker khởi tạo → Trạng thái: "Chờ duyệt". 2.Kế toán phó xác thực 2FA và duyệt xong → Trạng thái: "Chờ duyệt cấp tiếp theo". 3.Kế toán trưởng xác thực 2FA và duyệt xong → Trạng thái: "Chờ duyệt cấp tiếp theo". 4.Chủ tài khoản ký số thành công → Trạng thái: "Chờ ký số pháp nhân". 5.Người đại diện pháp nhân ký số pháp nhân thành công → Hệ thống hiển thị màn hình thông báo thành công, bản ghi chuyển trạng thái "Đã gửi ngân hàng". | O5: Critical | P5: Cần xác nhận: 2FA/OTP; Cần xác nhận: ký số (USB token/HSM?) | S5: Not started
A6: 5 | B6: FO-E2E | C6: HF-02 | D6: 1 cấp, có ký số PN | E6: Kiểm tra luồng | F6: Happy – E2E | G6: Tạo đề nghị phát hành | H6: Kiểm tra luồng | I6: Luồng lưu nháp rồi phát hành 1 cấp duyệt có ký số pháp nhân | K6: Kiểm tra luồng-Thành công-Tạo đề nghị phát hành-Luồng lưu nháp rồi phát hành 1 cấp duyệt có ký số pháp nhân-- | L6: 1 Marker 1 Kế toán trưởng 1 Chủ tài khoản 1 Người ký pháp nhân | M6: Step: 1.User Maker login hệ thống FO, thêm mới bản ghi phát hành LC, nhập liệu đầy đủ. 2.Maker thực hiện <Lưu nháp>. 3.Maker mở lại bản ghi vừa lưu nháp, đẩy giao dịch lên cấp duyệt → bản ghi chuyển "Chờ duyệt". 4.User Kế toán trưởng login, thực hiện xác thực 2FA và Phê duyệt. 5.User Chủ tài khoản login, thực hiện Ký số thành công. 6.Người dùng có thẩm quyền Ký số pháp nhân login, thực hiện ký số pháp nhân thành công. 7.Quan sát kết quả. | N6: 1.Maker khởi tạo → Trạng thái: "Khởi tạo phát hành". 2.Maker lưu nháp → Trạng thái: "Bản nháp". 3.Maker đẩy giao dịch lên cấp duyệt → Trạng thái: "Chờ duyệt". 4.Kế toán trưởng xác thực 2FA và duyệt xong → Trạng thái: "Chờ duyệt". 5.Chủ tài khoản ký số thành công → Trạng thái: "Chờ ký số pháp nhân". 6.Người đại diện pháp nhân ký số pháp nhân thành công → Hệ thống hiển thị màn hình thông báo thành công, bản ghi chuyển trạng thái "Đã gửi ngân hàng". | O6: High | P6: Cần xác nhận: 2FA/OTP; Cần xác nhận: ký số (USB token/HSM?) | S6: Not started
A7: 6 | B7: FO-E2E | C7: HF-02 | D7: 2 cấp, có ký số PN | E7: Kiểm tra luồng | F7: Happy – E2E | G7: Tạo đề nghị phát hành | H7: Kiểm tra luồng | I7: Luồng lưu nháp rồi phát hành 2 cấp duyệt có ký số pháp nhân | K7: Kiểm tra luồng-Thành công-Tạo đề nghị phát hành-Luồng lưu nháp rồi phát hành 1 cấp duyệt có ký số pháp nhân-- | L7: 1 Marker 1 Kế toán trưởng 1 Kế toán phó 1 Chủ tài khoản 1 Người ký pháp nhân | M7: Step: 1.User Maker login hệ thống FO, thêm mới bản ghi phát hành LC, nhập liệu đầy đủ. 2.Maker thực hiện <Lưu nháp>. 3.Maker mở lại bản ghi vừa lưu nháp, đẩy giao dịch lên cấp duyệt → "Chờ duyệt". 4.User Kế toán phó login, xác thực 2FA và Phê duyệt → bản ghi chuyển "Chờ duyệt cấp tiếp theo". 5.User Kế toán trưởng login, xác thực 2FA và Phê duyệt. 6.User Chủ tài khoản login, thực hiện Ký số thành công → "Chờ ký số pháp nhân". 7.Người dùng có thẩm quyền Ký số pháp nhân thực hiện ký số pháp nhân thành công. 8.Quan sát kết quả. | N7: 1.Maker khởi tạo → Trạng thái: "Khởi tạo phát hành". 2.Maker lưu nháp → Trạng thái: "Bản nháp". 3.Maker đẩy giao dịch lên cấp duyệt → Trạng thái: "Chờ duyệt". 4.Kế toán phó xác thực 2FA và duyệt xong → Trạng thái: "Chờ duyệt cấp tiếp theo". 5.Kế toán trưởng xác thực 2FA và duyệt xong → Trạng thái: "Chờ duyệt cấp tiếp theo". 6.Chủ tài khoản ký số thành công → Trạng thái: "Chờ ký số pháp nhân". 7.Người đại diện pháp nhân ký số pháp nhân thành công → Hệ thống hiển thị màn hình thông báo thành công, bản ghi chuyển trạng thái "Đã gửi ngân hàng". | O7: High | P7: Cần xác nhận: 2FA/OTP; Cần xác nhận: ký số (USB token/HSM?) | S7: Not started
A8: 7 | B8: FO-E2E | C8: HF-02 | D8: 1 cấp, không ký số PN | E8: Kiểm tra luồng | F8: Happy – E2E | G8: Tạo đề nghị phát hành | H8: Kiểm tra luồng | I8: Luồng lưu nháp rồi phát hành 1 cấp duyệt không có ký số pháp nhân | K8: Kiểm tra luồng-Thành công-Tạo đề nghị phát hành-Luồng lưu nháp rồi phát hành 1 cấp duyệt không có ký số pháp nhân-- | L8: 1 Marker 1 Kế toán trưởng 1 Chủ tài khoản | M8: Step: 1.User Maker login hệ thống FO, thêm mới bản ghi phát hành LC, nhập liệu đầy đủ. 2.Maker thực hiện <Lưu nháp>. 3.Maker mở lại bản ghi vừa lưu nháp, đẩy giao dịch lên cấp duyệt → bản ghi chuyển "Chờ duyệt". 4.User Kế toán trưởng login, thực hiện xác thực 2FA và Phê duyệt. 5.User Chủ tài khoản login, thực hiện Ký số thành công. 6.Quan sát kết quả. | N8: 1.Maker khởi tạo → Trạng thái: "Khởi tạo phát hành". 2.Maker lưu nháp → Trạng thái: "Bản nháp". 3.Maker đẩy giao dịch lên cấp duyệt → Trạng thái: "Chờ duyệt". 4.Kế toán trưởng xác thực 2FA và duyệt xong → Trạng thái: "Chờ duyệt". 5.Chủ tài khoản ký số thành công → Hệ thống hiển thị màn hình thông báo thành công, bản ghi chuyển trạng thái "Đã gửi ngân hàng". | O8: High | P8: Cần xác nhận: 2FA/OTP; Cần xác nhận: ký số (USB token/HSM?) | S8: Not started
A9: 8 | B9: FO-E2E | C9: HF-02 | D9: 2 cấp, không ký số PN | E9: Kiểm tra luồng | F9: Happy – E2E | G9: Tạo đề nghị phát hành | H9: Kiểm tra luồng | I9: Luồng lưu nháp rồi phát hành 2 cấp duyệt không có ký số pháp nhân | K9: Kiểm tra luồng-Thành công-Tạo đề nghị phát hành-Luồng lưu nháp rồi phát hành 2 cấp duyệt không có ký số pháp nhân-- | L9: 1 Marker 1 Kế toán trưởng 1 Kế toán phó 1 Chủ tài khoản | M9: Step: 1.User Maker login hệ thống FO, thêm mới bản ghi phát hành LC, nhập liệu đầy đủ. 2.Maker thực hiện <Lưu nháp>. 3.Maker mở lại bản ghi vừa lưu nháp, đẩy giao dịch lên cấp duyệt → bản ghi chuyển "Chờ duyệt". 4.User Kế toán phó login, thực hiện xác thực 2FA và Phê duyệt → bản ghi chuyển "Chờ duyệt cấp tiếp theo". 5.User Kế toán trưởng login, thực hiện xác thực 2FA và Phê duyệt. 6.User Chủ tài khoản login, thực hiện Ký số thành công. 7.Quan sát kết quả. | N9: 1.Maker khởi tạo → Trạng thái: "Khởi tạo phát hành". 2.Maker lưu nháp → Trạng thái: "Bản nháp". 3.Maker đẩy giao dịch lên cấp duyệt → Trạng thái: "Chờ duyệt". 4.Kế toán phó xác thực 2FA và duyệt xong → Trạng thái: "Chờ duyệt cấp tiếp theo". 5.Kế toán trưởng xác thực 2FA và duyệt xong → Trạng thái: "Chờ duyệt cấp tiếp theo". 6.Chủ tài khoản ký số thành công → Hệ thống hiển thị màn hình thông báo thành công, bản ghi chuyển trạng thái "Đã gửi ngân hàng". | O9: High | P9: Cần xác nhận: 2FA/OTP; Cần xác nhận: ký số (USB token/HSM?) | S9: Not started
A10: 9 | B10: FO-E2E | C10: NE | D10: Hủy giao dịch từ bản nháp → Đã hủy | E10: Kiểm tra luồng | F10: Negative – E2E | G10: Tạo đề nghị phát hành | H10: Kiểm tra luồng | I10: Hủy giao dịch từ bản nháp | K10: Kiểm tra luồng-Thành công-Tạo đề nghị phát hành-Luồng lưu nháp rồi phát hành 2 cấp duyệt có ký số pháp nhân-- | L10: 1 Marker | M10: Step: 1.User Maker login hệ thống FO, thêm mới bản ghi phát hành LC, nhập liệu đầy đủ. 2.Maker thực hiện <Lưu nháp>. 3.Maker mở lại bản ghi, chọn chức năng <Hủy đề nghị>, xác nhận hủy. 4.Quan sát kết quả. | N10: 1.Maker khởi tạo → Trạng thái: "Khởi tạo phát hành". 2.Maker lưu nháp → Trạng thái: "Bản nháp". 3.Maker thực hiện hủy đề nghị → Trạng thái: "Đã hủy". | O10: High | P10: Cần xác nhận: ký số (USB token/HSM?) | S10: Not started
A11: 10 | B11: FO-E2E | C11: NE | D11: Từ chối tại Kế toán trưởng → Đã hủy | E11: Kiểm tra luồng | F11: Negative – E2E | G11: Tạo đề nghị phát hành | H11: Kiểm tra luồng | I11: Từ chối tại Kế toán trưởng | K11: Kiểm tra luồng-Thành công-Tạo đề nghị phát hành-Luồng lưu nháp rồi phát hành 1 cấp duyệt không có ký số pháp nhân-- | L11: 1 Marker 1 Checker | M11: Step: 1.User Maker login hệ thống FO, thêm mới bản ghi phát hành LC, nhập liệu đầy đủ, đẩy giao dịch lên cấp duyệt → bản ghi chuyển "Chờ duyệt". 2.User Kế toán trưởng (Checker) login, truy cập bản ghi, chọn <Từ chối>, nhập lý do, xác nhận. 3.Quan sát kết quả. | N11: 1.Maker khởi tạo → Trạng thái: "Chờ duyệt". 2.Kế toán trưởng từ chối bản ghi → Trạng thái: "Đã hủy". | O11: Critical | P11: Cần xác nhận: ký số (USB token/HSM?) | S11: Not started
A12: 11 | B12: FO-E2E | C12: NE | D12: Từ chối tại Chủ tài khoản → Từ chối | E12: Kiểm tra luồng | F12: Negative – E2E | G12: Tạo đề nghị phát hành | H12: Kiểm tra luồng | I12: Từ chối tại Chủ tài khoản | K12: Kiểm tra luồng-từ chối giao dịch-Tạo đề nghị phát hành-Từ chối tại Chủ tài khoản-- | L12: 1 Marker 1 Kế toán trưởng 1 Chủ tài khoản | M12: Step: 1.User Maker login hệ thống FO, thêm mới bản ghi phát hành LC, nhập liệu đầy đủ, đẩy giao dịch lên cấp duyệt → "Chờ duyệt". 2.User Kế toán trưởng login, thực hiện xác thực 2FA và Phê duyệt giao dịch → bản ghi chuyển "Chờ duyệt cấp tiếp theo". 3.User Chủ tài khoản login, chọn <Từ chối> bản ghi, nhập lý do, xác nhận. 4.Quan sát kết quả. | N12: 1.Maker khởi tạo → Trạng thái: "Chờ duyệt". 2.Kế toán trưởng xác thực 2FA và duyệt xong → Trạng thái: "Chờ duyệt cấp tiếp theo". 3.Chủ tài khoản từ chối bản ghi → Trạng thái: "Từ chối". | O12: Critical | P12: Cần xác nhận: 2FA/OTP | S12: Not started
A13: 12 | B13: FO-E2E | C13: NE | D13: Bước Ký số pháp nhân KHÔNG có nút Từ chối | E13: Kiểm tra luồng | F13: Negative – E2E | G13: Tạo đề nghị phát hành | H13: Kiểm tra luồng | I13: Kiểm tra bước Ký số pháp nhân KHÔNG có tùy chọn Từ chối | K13: Kiểm tra luồng-Thành công-Tạo đề nghị phát hành-Kiểm tra bước Ký số pháp nhân KHÔNG có tùy chọn Từ chối-- | L13: 1 Marker 1 Kế toán trưởng 1 Chủ tài khoản 1 Người ký pháp nhân | M13: Step: 1.User Maker login hệ thống FO, thêm mới bản ghi phát hành LC, nhập liệu đầy đủ, đẩy giao dịch lên cấp duyệt. 2.User Kế toán trưởng login, thực hiện xác thực 2FA và Phê duyệt. 3.User Chủ tài khoản login, thực hiện Ký số thành công → bản ghi chuyển "Chờ ký số pháp nhân". 4.Người dùng có thẩm quyền Ký số pháp nhân login, mở màn hình xử lý bản ghi. 5.Quan sát các nút chức năng hiển thị trên màn hình. | N13: Tại bước "Chờ ký số pháp nhân", màn hình KHÔNG hiển thị nút <Từ chối> — người dùng có thẩm quyền Ký số pháp nhân chỉ có thể thực hiện Ký số pháp nhân (đồng ý) để hoàn tất giao dịch, không có quyền từ chối giao dịch tại bước này. | O13: Medium | P13: Cần xác nhận: 2FA/OTP; Cần xác nhận: ký số (USB token/HSM?) | S13: Not started
A14: 13 | B14: FO-E2E | C14: NE | D14: Trả lại → Maker hủy → Đã hủy | E14: Kiểm tra luồng | F14: Negative – E2E | G14: Tạo đề nghị phát hành | H14: Kiểm tra luồng | I14: Yêu cầu chỉnh sửa rồi hủy | K14: Kiểm tra luồng-Huỷ giao dịch-Tạo đề nghị phát hành-Hủy giao dịch từ bản nháp-- | L14: 1 Marker 1 Checker | M14: Step: 1.User Maker login hệ thống FO, thêm mới bản ghi phát hành LC, nhập liệu đầy đủ, đẩy giao dịch lên cấp duyệt → "Chờ duyệt". 2.User Kế toán trưởng (Checker) login, truy cập bản ghi, chọn <Trả lại>, nhập ý kiến, xác nhận. 3.User Maker mở lại giao dịch (nay ở trạng thái "Yêu cầu chỉnh sửa"), chọn chức năng <Hủy đề nghị>, xác nhận hủy. 4.Quan sát kết quả. | N14: 1.Maker khởi tạo → Trạng thái: "Chờ duyệt". 2.Kế toán trưởng trả lại bản ghi → Trạng thái: "Yêu cầu chỉnh sửa". 3.Maker thực hiện hủy giao dịch → Trạng thái: "Đã hủy". | O14: High | S14: Not started
A15: 14 | B15: FO-E2E | C15: HF-03 | D15: 1 cấp, không ký số PN | E15: Kiểm tra luồng | F15: Happy – E2E | G15: Tạo đề nghị phát hành | H15: Kiểm tra luồng | I15: Yêu cầu chỉnh sửa rồi phát hành thành công luồng duyệt 1 cấp không ký số pháp nhân | K15: Kiểm tra luồng-từ chối giao dịch-Tạo đề nghị phát hành-Từ chối tại Kế toán trưởng-- | L15: 1 Marker 1 Kế toán trưởng 1 Chủ tài khoản | M15: Step: 1.User Maker login hệ thống FO, thêm mới bản ghi phát hành LC, nhập liệu đầy đủ, đẩy giao dịch lên cấp duyệt → "Chờ duyệt". 2.User Kế toán trưởng login, chọn <Trả lại>, nhập ý kiến, xác nhận → bản ghi chuyển "Yêu cầu chỉnh sửa". 3.User Maker mở lại giao dịch, chỉnh sửa thông tin theo ý kiến, gửi lại bản ghi → bản ghi chuyển "Chờ duyệt". 4.User Kế toán trưởng thực hiện xác thực 2FA và Phê duyệt. 5.User Chủ tài khoản thực hiện Ký số thành công. 6.Quan sát kết quả. | N15: 1.Maker khởi tạo → Trạng thái: "Chờ duyệt". 2.Kế toán trưởng thực hiện Trả lại → Trạng thái: "Yêu cầu chỉnh sửa". 3.Maker chỉnh sửa và gửi lại bản ghi → Trạng thái: "Chờ duyệt". 4.Kế toán trưởng xác thực 2FA và duyệt xong → Trạng thái: "Chờ duyệt". 5.Chủ tài khoản ký số thành công → Hệ thống hiển thị màn hình thông báo thành công, bản ghi chuyển trạng thái "Đã gửi ngân hàng". | O15: Critical | P15: Cần xác nhận: 2FA/OTP; Cần xác nhận: ký số (USB token/HSM?) | S15: Not started
A16: 15 | B16: FO-E2E | C16: HF-03 | D16: 1 cấp, có ký số PN | E16: Kiểm tra luồng | F16: Happy – E2E | G16: Tạo đề nghị phát hành | H16: Kiểm tra luồng | I16: Yêu cầu chỉnh sửa rồi phát hành thành công luồng duyệt 1 cấp có ký số pháp nhân | K16: Kiểm tra luồng-từ chối giao dịch-Tạo đề nghị phát hành-Từ chối tại Chủ tài khoản-- | L16: 1 Marker 1 Kế toán trưởng 1 Chủ tài khoản 1 Người ký pháp nhân | M16: Step: 1.User Maker login hệ thống FO, thêm mới bản ghi phát hành LC, nhập liệu đầy đủ, đẩy giao dịch lên cấp duyệt → "Chờ duyệt". 2.User Kế toán trưởng login, chọn <Trả lại>, nhập ý kiến, xác nhận → bản ghi chuyển "Yêu cầu chỉnh sửa". 3.User Maker chỉnh sửa thông tin, gửi lại bản ghi → "Chờ duyệt". 4.User Kế toán trưởng thực hiện xác thực 2FA và Phê duyệt. 5.User Chủ tài khoản thực hiện Ký số thành công → "Chờ ký số pháp nhân". 6.Người đại diện pháp nhân thực hiện ký số pháp nhân thành công. 7.Quan sát kết quả. | N16: 1.Maker khởi tạo → Trạng thái: "Chờ duyệt". 2.Kế toán trưởng thực hiện Trả lại → Trạng thái: "Yêu cầu chỉnh sửa". 3.Maker chỉnh sửa và gửi lại bản ghi → Trạng thái: "Chờ duyệt". 4.Kế toán trưởng xác thực 2FA và duyệt xong → Trạng thái: "Chờ duyệt". 5.Chủ tài khoản ký số thành công → Trạng thái: "Chờ ký số pháp nhân". 6.Người đại diện pháp nhân ký số pháp nhân thành công → Hệ thống hiển thị màn hình thông báo thành công, bản ghi chuyển trạng thái "Đã gửi ngân hàng". | O16: Critical | P16: Cần xác nhận: 2FA/OTP; Cần xác nhận: ký số (USB token/HSM?) | S16: Not started
A17: 16 | B17: FO-E2E | C17: HF-03 | D17: 2 cấp, không ký số PN | E17: Kiểm tra luồng | F17: Happy – E2E | G17: Tạo đề nghị phát hành | H17: Kiểm tra luồng | I17: Yêu cầu chỉnh sửa rồi phát hành thành công luồng duyệt 2 cấp không ký số pháp nhân | K17: Kiểm tra luồng-Thành công-Tạo đề nghị phát hành-Kiểm tra bước Ký số pháp nhân KHÔNG có tùy chọn Từ chối-- | L17: 1 Marker 1 Kế toán trưởng 1 Kế toán phó 1 Chủ tài khoản | M17: Step: 1.User Maker login hệ thống FO, thêm mới bản ghi phát hành LC, nhập liệu đầy đủ, đẩy giao dịch lên cấp duyệt → "Chờ duyệt". 2.User Kế toán phó login, chọn <Trả lại>, nhập ý kiến, xác nhận → bản ghi chuyển "Yêu cầu chỉnh sửa". 3.User Maker chỉnh sửa thông tin, gửi lại bản ghi → "Chờ duyệt". 4.User Kế toán phó thực hiện xác thực 2FA và Phê duyệt → bản ghi chuyển "Chờ duyệt cấp tiếp theo". 5.User Kế toán trưởng thực hiện xác thực 2FA và Phê duyệt. 6.User Chủ tài khoản thực hiện Ký số thành công. 7.Quan sát kết quả. | N17: 1.Maker khởi tạo → Trạng thái: "Chờ duyệt". 2.Kế toán phó thực hiện Trả lại → Trạng thái: "Yêu cầu chỉnh sửa". 3.Maker chỉnh sửa và gửi lại bản ghi → Trạng thái: "Chờ duyệt". 4.Kế toán phó xác thực 2FA và duyệt xong → Trạng thái: "Chờ duyệt cấp tiếp theo". 5.Kế toán trưởng xác thực 2FA và duyệt xong → Trạng thái: "Chờ duyệt cấp tiếp theo". 6.Chủ tài khoản ký số thành công → Hệ thống hiển thị màn hình thông báo thành công, bản ghi chuyển trạng thái "Đã gửi ngân hàng". | O17: Critical | P17: Cần xác nhận: 2FA/OTP; Cần xác nhận: ký số (USB token/HSM?) | S17: Not started
A18: 17 | B18: FO-E2E | C18: HF-03 | D18: 2 cấp, có ký số PN | E18: Kiểm tra luồng | F18: Happy – E2E | G18: Tạo đề nghị phát hành | H18: Kiểm tra luồng | I18: Yêu cầu chỉnh sửa rồi phát hành thành công luồng duyệt 2 cấp có ký số pháp nhân | K18: Kiểm tra luồng-Huỷ giao dịch-Tạo đề nghị phát hành-Yêu cầu chỉnh sửa rồi hủy-- | L18: 1 Marker 1 Kế toán trưởng 1 Kế toán phó 1 Chủ tài khoản 1 Người ký pháp nhân | M18: Step: 1.User Maker login hệ thống FO, thêm mới bản ghi phát hành LC, nhập liệu đầy đủ, đẩy giao dịch lên cấp duyệt → "Chờ duyệt". 2.User Kế toán phó login, chọn <Trả lại>, nhập ý kiến, xác nhận → bản ghi chuyển "Yêu cầu chỉnh sửa". 3.User Maker chỉnh sửa thông tin, gửi lại bản ghi → "Chờ duyệt". 4.User Kế toán phó thực hiện xác thực 2FA và Phê duyệt → bản ghi chuyển "Chờ duyệt cấp tiếp theo". 5.User Kế toán trưởng thực hiện xác thực 2FA và Phê duyệt. 6.User Chủ tài khoản thực hiện Ký số thành công → "Chờ ký số pháp nhân". 7.Người đại diện pháp nhân thực hiện Ký số pháp nhân thành công. 8.Quan sát kết quả. | N18: 1.Maker khởi tạo → Trạng thái: "Chờ duyệt". 2.Kế toán phó thực hiện Trả lại → Trạng thái: "Yêu cầu chỉnh sửa". 3.Maker chỉnh sửa và gửi lại bản ghi → Trạng thái: "Chờ duyệt". 4.Kế toán phó xác thực 2FA và duyệt xong → Trạng thái: "Chờ duyệt cấp tiếp theo". 5.Kế toán trưởng xác thực 2FA và duyệt xong → Trạng thái: "Chờ duyệt cấp tiếp theo". 6.Chủ tài khoản ký số thành công → Trạng thái: "Chờ ký số pháp nhân". 7.Người đại diện pháp nhân ký số pháp nhân thành công → Hệ thống hiển thị màn hình thông báo thành công, bản ghi chuyển trạng thái "Đã gửi ngân hàng". | O18: Critical | P18: Cần xác nhận: 2FA/OTP; Cần xác nhận: ký số (USB token/HSM?) | S18: Not started
A19: 66 | B19: FO | C19: S01 | D19: Danh sách & tìm kiếm giao dịch | E19: HF-01/02/03 | F19: Edge case | G19: Danh sách và tìm kiếm giao dịch | H19: Kiểm tra quyền truy cập chức năng "Danh sách và tìm kiếm giao dịch" (FO) | I19: Kiểm tra quyền truy cập chức năng "Danh sách và tìm kiếm giao dịch" (FO) | K19: Kiểm tra luồng-Thất bại-BO - Luồng xử lý giao dịch Phát hành LC-Luồng (2) – Đề xuất từ chối - Không cần thẩm quyền BGĐ CN-CA lead phê duyệt (2), không thuộc thẩm quyền BGĐ CN → CA từ chối-LC không được phát hành | L19: 1 Marker | M19: Pre: - Tồn tại 1 hồ sơ đề nghị Phát hành LC có trạng thái khác Bản nháp Step: 1. Đăng nhập hệ thống bằng user có quyền xem chi tiết. 2. Mở màn hình xem chi tiết hồ sơ có trạng thái khác Bản nháp. 3. Quan sát khu vực các nút chức năng trên màn hình. | N19: Nút <Xóa đề nghị> không hiển thị trên màn hình (do BR quy định nút chỉ hiển thị với TT = Bản nháp). | O19: Medium | S19: Not started
A20: 67 | B20: FO | C20: S01 | D20: Danh sách & tìm kiếm giao dịch | E20: HF-01/02/03 | F20: Edge case | G20: Danh sách và tìm kiếm giao dịch | H20: Kiểm tra chặn truy cập chức năng "Danh sách và tìm kiếm giao dịch" (FO) khi không được phân quyền | I20: Kiểm tra chặn truy cập chức năng "Danh sách và tìm kiếm giao dịch" (FO) khi không được phân quyền | K20: Kiểm tra luồng-Thất bại-BO - Luồng xử lý giao dịch Phát hành LC-Luồng (2) – Đề xuất từ chối - Không cần thẩm quyền BGĐ CN-CRC lead phê duyệt (2), không thuộc thẩm quyền BGĐ CN → CA từ chối-LC không được phát hành | L20: 1 Marker | M20: Step: Đăng nhập hệ thống với user KHÔNG được phân quyền chức năng "Danh sách và tìm kiếm giao dịch", thử truy cập chức năng. | N20: User không nhìn thấy/không truy cập được chức năng "Danh sách và tìm kiếm giao dịch" trên giao diện. | O20: High | S20: Not started
A21: 68 | B21: FO | C21: S01 | D21: Danh sách & tìm kiếm giao dịch | E21: HF-01/02/03 | F21: Edge case | G21: Danh sách và tìm kiếm giao dịch | H21: Kiểm tra hệ thống gọi API tới BO Admin Portal để lấy thông tin phân quyền (CIF, cây phân quyền, roleName) ngay sau khi đăng nhập thành công | I21: Kiểm tra hệ thống gọi API tới BO Admin Portal để lấy thông tin phân quyền (CIF, cây phân quyền, roleName) ngay sau khi đăng nhập thành công | K21: Kiểm tra luồng-Thất bại-BO - Luồng xử lý giao dịch Phát hành LC-Luồng (2) – Đề xuất từ chối - Không cần thẩm quyền BGĐ CN-CA lead phê duyệt (2), không thuộc thẩm quyền BGĐ CN → quay lại CA, CA trả lại Doanh nghiệp → Doanh nghiệp hủy đề nghị-LC không được phát hành | L21: 1 Marker | M21: Pre: - NSD đã có tài khoản được cấp quyền truy vấn giao dịch (cây phân quyền TTTM > LCNK > Phát hành LC (PHLC) > Truy vấn hồ sơ (V_PHLC)) trên BO Admin Portal Step: 1. NSD đăng nhập thành công vào hệ thống. 2. NSD truy cập theo đường dẫn: Phát hành LC. 3. Quan sát màn hình Danh sách và tìm kiếm giao dịch phát hành LC. | N21: Hệ thống đã gọi API tới hệ thống BO Admin Portal để lấy thông tin CIF của user, cây phân quyền (Permission) và roleName theo đúng cây phân quyền 4 tầng: TTTM (Tài trợ thương mại) > LCNK (LC nhập khẩu) > Phát hành LC (Mã PHLC) > Truy vấn hồ sơ (Mã V_PHLC). Màn hình danh sách giao dịch phát hành LC hiển thị thành công cho NSD. | O21: High | P21: Cần xác nhận: gọi API ngoài | S21: Not started
A22: 69 | B22: FO | C22: S01 | D22: Danh sách & tìm kiếm giao dịch | E22: HF-01/02/03 | F22: Edge case | G22: Danh sách và tìm kiếm giao dịch | H22: Kiểm tra hậu điều kiện phân quyền theo CIF: NSD chỉ xem được toàn bộ danh sách giao dịch đề nghị phát hành LC thuộc chính CIF của mình | I22: Kiểm tra hậu điều kiện phân quyền theo CIF: NSD chỉ xem được toàn bộ danh sách giao dịch đề nghị phát hành LC thuộc chính CIF của mình | K22: Kiểm tra luồng-Thất bại-BO - Luồng xử lý giao dịch Phát hành LC-Luồng (2) – Đề xuất từ chối - Không cần thẩm quyền BGĐ CN-CRC lead phê duyệt (2), không thuộc thẩm quyền BGĐ CN → quay lại CA, CA trả lại Doanh nghiệp → Doanh nghiệp hủy đề nghị-LC không được phát hành | L22: 1 Marker | M22: Pre: - NSD đã đăng nhập thành công và được phân quyền truy vấn giao dịch (mã V_PHLC) trên CIF của DN đang login; hệ thống đang có giao dịch phát hành LC của nhiều CIF khác nhau Step: 1. NSD đăng nhập vào hệ thống với tài khoản thuộc CIF A. 2. NSD truy cập đường dẫn Phát hành LC. 3. Quan sát danh sách giao dịch hiển thị trên màn hình. | N22: Hệ thống chỉ hiển thị toàn bộ danh sách giao dịch đề nghị phát hành LC thuộc CIF A (CIF của user đang truy cập), không hiển thị giao dịch của CIF khác, đúng theo hậu điều kiện: "Xem được toàn bộ danh sách giao dịch của chính user truy cập". | O22: High | S22: Not started
A23: 70 | B23: FO | C23: S01 | D23: Danh sách & tìm kiếm giao dịch | E23: HF-01/02/03 | F23: Edge case | G23: Danh sách và tìm kiếm giao dịch | H23: Kiểm tra chức năng tìm kiếm nhanh (realtime) trên khung tìm kiếm theo trường Mã đề nghị | I23: Kiểm tra chức năng tìm kiếm nhanh (realtime) trên khung tìm kiếm theo trường Mã đề nghị | K23: Kiểm tra quyền truy cập chức năng "Danh sách và tìm kiếm giao dịch" (FO)-Thành công-Danh sách và tìm kiếm giao dịch-Kiểm tra quyền truy cập chức năng "Danh sách và tìm kiếm giao dịch" (FO)-- | L23: 1 Marker | M23: Pre: - NSD đã đăng nhập và đang ở màn hình danh sách giao dịch phát hành LC, có sẵn dữ liệu giao dịch Step: 1. Tại khung tìm kiếm, NSD nhập giá trị hợp lệ (một phần hoặc toàn bộ) vào trường [Mã đề nghị]. 2. Quan sát danh sách kết quả mà không cần nhấn thêm nút tìm kiếm nào khác. | N23: Hệ thống trả kết quả hiển thị realtime trên danh sách, chỉ hiển thị các giao dịch có Mã đề nghị chứa (CONTAIN) giá trị NSD vừa nhập. | O23: High | S23: Not started
A24: 71 | B24: FO | C24: S01 | D24: Danh sách & tìm kiếm giao dịch | E24: HF-01/02/03 | F24: Edge case | G24: Danh sách và tìm kiếm giao dịch | H24: Kiểm tra chức năng tìm kiếm nhanh (realtime) trên khung tìm kiếm theo trường Bên nhận LC | I24: Kiểm tra chức năng tìm kiếm nhanh (realtime) trên khung tìm kiếm theo trường Bên nhận LC | K24: Kiểm tra chặn truy cập chức năng "Danh sách và tìm kiếm giao dịch" (FO) khi không được phân quyền-Thành công-Danh sách và tìm kiếm giao dịch-Kiểm tra chặn truy cập chức năng "Danh sách và tìm kiếm giao dịch" (FO) khi không được phân quyền-- | L24: 1 Marker | M24: Pre: - NSD đã đăng nhập và đang ở màn hình danh sách giao dịch phát hành LC, có sẵn dữ liệu giao dịch Step: 1. Tại khung tìm kiếm, NSD nhập giá trị hợp lệ vào trường [Bên nhận LC]. 2. Quan sát danh sách kết quả. | N24: Hệ thống trả kết quả hiển thị realtime trên danh sách, chỉ hiển thị các giao dịch có Bên nhận LC chứa (CONTAIN) giá trị NSD vừa nhập. | O24: Medium | S24: Not started
A25: 72 | B25: FO | C25: S01 | D25: Danh sách & tìm kiếm giao dịch | E25: HF-01/02/03 | F25: Edge case | G25: Danh sách và tìm kiếm giao dịch | H25: Kiểm tra chức năng tìm kiếm nhanh (realtime) trên khung tìm kiếm theo trường Số tiền | I25: Kiểm tra chức năng tìm kiếm nhanh (realtime) trên khung tìm kiếm theo trường Số tiền | K25: Kiểm tra hệ thống gọi API tới BO Admin Portal để lấy thông tin phân quyền (CIF, cây phân quyền, roleName) ngay sau khi đăng nhập thành công-Thành công-Danh sách và tìm kiếm giao dịch-Kiểm tra hệ thống gọi API tới BO Admin Portal để lấy thông tin phân quyền (CIF, cây phân quyền, roleName) ngay sau khi đăng nhập thành công-- | L25: 1 Marker | M25: Pre: - NSD đã đăng nhập và đang ở màn hình danh sách giao dịch phát hành LC, có sẵn dữ liệu giao dịch Step: 1. Tại khung tìm kiếm, NSD nhập giá trị vào trường [Số tiền]. 2. Quan sát danh sách kết quả. | N25: Hệ thống trả kết quả hiển thị realtime trên danh sách, chỉ hiển thị các giao dịch có Số tiền chứa (CONTAIN) giá trị NSD vừa nhập. | O25: Medium | P25: Cần xác nhận: gọi API ngoài | S25: Not started
A26: 73 | B26: FO | C26: S01 | D26: Danh sách & tìm kiếm giao dịch | E26: HF-01/02/03 | F26: Edge case | G26: Danh sách và tìm kiếm giao dịch | H26: Kiểm tra chức năng mở màn hình Bộ lọc nâng cao khi nhấn nút <Bộ lọc> | I26: Kiểm tra chức năng mở màn hình Bộ lọc nâng cao khi nhấn nút <Bộ lọc> | K26: Kiểm tra hậu điều kiện phân quyền theo CIF: NSD chỉ xem được toàn bộ danh sách giao dịch đề nghị phát hành LC thuộc chính CIF của mình-Thành công-Danh sách và tìm kiếm giao dịch-Kiểm tra hậu điều kiện phân quyền theo CIF: NSD chỉ xem được toàn bộ danh sách giao dịch đề nghị phát hành LC thuộc chính CIF của mình-- | L26: 1 Marker | M26: Pre: - NSD đã đăng nhập và đang ở màn hình danh sách giao dịch phát hành LC Step: 1. NSD nhấn nút <Bộ lọc>. | N26: Hệ thống mở màn hình bộ lọc nâng cao cho NSD nhập điều kiện tìm kiếm. | O26: Medium | S26: Not started
A27: 74 | B27: FO | C27: S01 | D27: Danh sách & tìm kiếm giao dịch | E27: HF-01/02/03 | F27: Edge case | G27: Danh sách và tìm kiếm giao dịch | H27: Kiểm tra chức năng tìm kiếm bằng Bộ lọc nâng cao khi nhập nhiều điều kiện và nhấn <Áp dụng>, đảm bảo điều kiện giữa các trường là quan hệ AND | I27: Kiểm tra chức năng tìm kiếm bằng Bộ lọc nâng cao khi nhập nhiều điều kiện và nhấn <Áp dụng>, đảm bảo điều kiện giữa các trường là quan hệ AND | K27: Kiểm tra chức năng tìm kiếm nhanh (realtime) trên khung tìm kiếm theo trường Mã đề nghị-Thành công-Danh sách và tìm kiếm giao dịch-Kiểm tra chức năng tìm kiếm nhanh (realtime) trên khung tìm kiếm theo trường Mã đề nghị-- | L27: 1 Marker | M27: Pre: - NSD đã đăng nhập, đang ở màn hình danh sách giao dịch phát hành LC và đã mở màn hình bộ lọc nâng cao; có sẵn dữ liệu giao dịch thỏa và không thỏa đồng thời các điều kiện sẽ nhập Step: 1. NSD nhấn nút <Bộ lọc> để mở màn hình bộ lọc nâng cao. 2. NSD nhập đồng thời từ 2 điều kiện tìm kiếm trở lên (ví dụ: Mã đề nghị và Bên nhận LC). 3. NSD nhấn <Áp dụng>. | N27: Hệ thống tìm và hiển thị kết quả tìm kiếm bên dưới, chỉ trả về các giao dịch thỏa mãn đồng thời tất cả các điều kiện đã nhập (quan hệ AND giữa các trường trên khung tìm kiếm). | O27: High | S27: Not started
A28: 75 | B28: FO | C28: S01 | D28: Danh sách & tìm kiếm giao dịch | E28: HF-01/02/03 | F28: Edge case | G28: Danh sách và tìm kiếm giao dịch | H28: Kiểm tra quy tắc tìm kiếm CONTAIN (chứa giá trị nhập) và không phân biệt hoa/thường khi tìm kiếm | I28: Kiểm tra quy tắc tìm kiếm CONTAIN (chứa giá trị nhập) và không phân biệt hoa/thường khi tìm kiếm | K28: Kiểm tra chức năng tìm kiếm nhanh (realtime) trên khung tìm kiếm theo trường Bên nhận LC-Thành công-Danh sách và tìm kiếm giao dịch-Kiểm tra chức năng tìm kiếm nhanh (realtime) trên khung tìm kiếm theo trường Bên nhận LC-- | L28: 1 Marker | M28: Pre: - NSD đã đăng nhập, đang ở màn hình danh sách giao dịch phát hành LC; có sẵn giao dịch mà giá trị trường tìm kiếm chứa chuỗi ký tự dự kiến nhập, viết hoa/thường khác với chuỗi sẽ nhập Step: 1. NSD nhập một chuỗi ký tự chỉ là một phần giá trị của trường tìm kiếm (ví dụ một phần Mã đề nghị), với cách viết hoa/thường khác với dữ liệu gốc trong hệ thống. 2. Quan sát kết quả trả về trên danh sách. | N28: Hệ thống áp dụng quy tắc tìm kiếm "CONTAIN" (có chứa chuỗi nhập) và không phân biệt chữ hoa/chữ thường, trả về đầy đủ các giao dịch có giá trị trường tìm kiếm chứa chuỗi đã nhập bất kể cách viết hoa/thường. | O28: Medium | S28: Not started
A29: 76 | B29: FO | C29: S01 | D29: Danh sách & tìm kiếm giao dịch | E29: HF-01/02/03 | F29: Edge case | G29: Danh sách và tìm kiếm giao dịch | H29: Kiểm tra kết quả tìm kiếm/danh sách được sắp xếp ưu tiên theo Ngày đề nghị giảm dần | I29: Kiểm tra kết quả tìm kiếm/danh sách được sắp xếp ưu tiên theo Ngày đề nghị giảm dần | K29: Kiểm tra chức năng tìm kiếm nhanh (realtime) trên khung tìm kiếm theo trường Số tiền-Thành công-Danh sách và tìm kiếm giao dịch-Kiểm tra chức năng tìm kiếm nhanh (realtime) trên khung tìm kiếm theo trường Số tiền-- | L29: 1 Marker | M29: Pre: - NSD đã đăng nhập, đang ở màn hình danh sách giao dịch phát hành LC; có sẵn nhiều giao dịch với Ngày đề nghị khác nhau Step: 1. NSD vào màn hình danh sách giao dịch phát hành LC (hoặc thực hiện tìm kiếm/lọc ra nhiều kết quả). 2. Quan sát thứ tự các bản ghi hiển thị trên danh sách kết quả. | N29: Kết quả được hiển thị theo thứ tự ưu tiên 1: theo [Ngày đề nghị] giảm dần (giao dịch có Ngày đề nghị mới nhất hiển thị trên cùng). | O29: Medium | S29: Not started
A30: 77 | B30: FO | C30: S01 | D30: Danh sách & tìm kiếm giao dịch | E30: HF-01/02/03 | F30: Edge case | G30: Danh sách và tìm kiếm giao dịch | H30: Kiểm tra chức năng phân trang: hiển thị 10 bản ghi/trang và cho phép xem thêm bản ghi khi còn bản ghi bị ẩn | I30: Kiểm tra chức năng phân trang: hiển thị 10 bản ghi/trang và cho phép xem thêm bản ghi khi còn bản ghi bị ẩn | K30: Kiểm tra chức năng mở màn hình Bộ lọc nâng cao khi nhấn nút <Bộ lọc>-Thành công-Danh sách và tìm kiếm giao dịch-Kiểm tra chức năng mở màn hình Bộ lọc nâng cao khi nhấn nút <Bộ lọc>-- | L30: 1 Marker | M30: Pre: - NSD đã đăng nhập, đang ở màn hình danh sách giao dịch phát hành LC; hệ thống có nhiều hơn 10 giao dịch thỏa điều kiện hiển thị/tìm kiếm Step: 1. NSD vào màn hình danh sách giao dịch phát hành LC (hoặc thực hiện tìm kiếm/lọc ra hơn 10 kết quả). 2. Quan sát số bản ghi hiển thị trên trang đầu tiên. 3. Kiểm tra khu vực phân trang và thực hiện thao tác chọn xem thêm bản ghi. | N30: Hệ thống hiển thị đúng 10 bản ghi cho một trang. Vì còn bản ghi bị ẩn (chưa hiển thị hết), hệ thống hiển thị phân trang, cho phép NSD chọn xem thêm bản ghi tiếp theo. | O30: Medium | S30: Not started
A31: 78 | B31: FO | C31: S01 | D31: Danh sách & tìm kiếm giao dịch | E31: HF-01/02/03 | F31: Edge case | G31: Danh sách và tìm kiếm giao dịch | H31: Kiểm tra thông báo khi tìm kiếm/lọc không có kết quả phù hợp | I31: Kiểm tra thông báo khi tìm kiếm/lọc không có kết quả phù hợp | K31: Kiểm tra chức năng tìm kiếm bằng Bộ lọc nâng cao khi nhập nhiều điều kiện và nhấn <Áp dụng>, đảm bảo điều kiện giữa các trường là quan hệ AND-Thành công-Danh sách và tìm kiếm giao dịch-Kiểm tra chức năng tìm kiếm bằng Bộ lọc nâng cao khi nhập nhiều điều kiện và nhấn <Áp dụng>, đảm bảo điều kiện giữa các trường là quan hệ AND-- | L31: 1 Marker | M31: Pre: - NSD đã đăng nhập, đang ở màn hình danh sách giao dịch phát hành LC Step: 1. NSD nhập điều kiện tìm kiếm trên khung tìm kiếm (hoặc bộ lọc nâng cao rồi nhấn <Áp dụng>) với giá trị không khớp với bất kỳ giao dịch nào trong danh sách. 2. Quan sát kết quả trả về. | N31: Hệ thống không trả về bản ghi nào và hiển thị thông báo MSG2 "Không tìm thấy kết quả phù hợp". | O31: High | S31: Not started
A32: 79 | B32: FO | C32: S01 | D32: Danh sách & tìm kiếm giao dịch | E32: HF-01/02/03 | F32: Edge case | G32: Danh sách và tìm kiếm giao dịch | H32: Thêm mới LC | I32: Kiểm tra chức năng nút "Thêm mới LC" | K32: Kiểm tra quy tắc tìm kiếm CONTAIN (chứa giá trị nhập) và không phân biệt hoa/thường khi tìm kiếm-Thành công-Danh sách và tìm kiếm giao dịch-Kiểm tra quy tắc tìm kiếm CONTAIN (chứa giá trị nhập) và không phân biệt hoa/thường khi tìm kiếm-- | L32: 1 Marker | M32: Step: Tại màn hình, nhấn nút "Thêm mới LC" và quan sát kết quả xử lý. | N32: Hệ thống thực hiện đúng chức năng của nút "Thêm mới LC" theo mô tả nghiệp vụ: Khi chọn, hệ thống mở màn hình Thêm mới đề nghị phát hành | O32: Medium | S32: Not started
A33: 80 | B33: FO | C33: S01 | D33: Danh sách & tìm kiếm giao dịch | E33: HF-01/02/03 | F33: Edge case | G33: Danh sách và tìm kiếm giao dịch | H33: Tìm kiếm | I33: Kiểm tra giới hạn độ dài dữ liệu nhập trường "Tìm kiếm" (tối đa 50 ký tự) | K33: Kiểm tra kết quả tìm kiếm/danh sách được sắp xếp ưu tiên theo Ngày đề nghị giảm dần-Thành công-Danh sách và tìm kiếm giao dịch-Kiểm tra kết quả tìm kiếm/danh sách được sắp xếp ưu tiên theo Ngày đề nghị giảm dần-- | L33: 1 Marker | M33: Step: Nhập giá trị dài hơn 50 ký tự vào trường "Tìm kiếm" và thực hiện Lưu/Gửi duyệt. | N33: Hệ thống không cho nhập quá 50 ký tự hoặc chặn lưu/hiển thị cảnh báo vượt quá độ dài cho phép. | O33: Medium | S33: Not started
A34: 81 | B34: FO | C34: S01 | D34: Danh sách & tìm kiếm giao dịch | E34: HF-01/02/03 | F34: Edge case | G34: Danh sách và tìm kiếm giao dịch | H34: Ngày đề nghị | I34: Kiểm tra định dạng ngày trường "Ngày đề nghị" | K34: Kiểm tra chức năng phân trang: hiển thị 10 bản ghi/trang và cho phép xem thêm bản ghi khi còn bản ghi bị ẩn-Thành công-Danh sách và tìm kiếm giao dịch-Kiểm tra chức năng phân trang: hiển thị 10 bản ghi/trang và cho phép xem thêm bản ghi khi còn bản ghi bị ẩn-- | L34: 1 Marker | M34: Step: Nhập giá trị sai định dạng ngày vào trường "Ngày đề nghị" (ví dụ nhập chữ hoặc ngày không hợp lệ 31/13/2026). | N34: Hệ thống không cho nhập/hiển thị cảnh báo định dạng ngày không hợp lệ. | O34: Medium | S34: Not started
A35: 82 | B35: FO | C35: S01 | D35: Danh sách & tìm kiếm giao dịch | E35: HF-01/02/03 | F35: Edge case | G35: Danh sách và tìm kiếm giao dịch | H35: Ngày đề nghị | I35: Kiểm tra nhập giá trị ngày hợp lệ trường "Ngày đề nghị" | K35: Kiểm tra thông báo khi tìm kiếm/lọc không có kết quả phù hợp-Thành công-Danh sách và tìm kiếm giao dịch-Kiểm tra thông báo khi tìm kiếm/lọc không có kết quả phù hợp-- | L35: 1 Marker | M35: Step: Chọn/nhập 1 giá trị ngày hợp lệ cho trường "Ngày đề nghị" rồi Lưu/Gửi duyệt. | N35: Hệ thống chấp nhận và hiển thị đúng giá trị ngày đã nhập, theo mô tả: Cho phép nhập dữ liệu Nhập trong khoảng Từ ngày – Đến ngày Không cho Từ ngày > Đến ngày | O35: Medium | S35: Not started
A36: 83 | B36: FO | C36: S01 | D36: Danh sách & tìm kiếm giao dịch | E36: HF-01/02/03 | F36: Edge case | G36: Danh sách và tìm kiếm giao dịch | H36: Số tham chiếu LC | I36: Kiểm tra giới hạn độ dài dữ liệu nhập trường "Số tham chiếu LC" (tối đa 20 ký tự) | K36: Thêm mới LC-Thành công-Danh sách và tìm kiếm giao dịch-Kiểm tra chức năng nút "Thêm mới LC"-- | L36: 1 Marker | M36: Step: Nhập giá trị dài hơn 20 ký tự vào trường "Số tham chiếu LC" và thực hiện Lưu/Gửi duyệt. | N36: Hệ thống không cho nhập quá 20 ký tự hoặc chặn lưu/hiển thị cảnh báo vượt quá độ dài cho phép. | O36: Medium | S36: Not started
A37: 84 | B37: FO | C37: S01 | D37: Danh sách & tìm kiếm giao dịch | E37: HF-01/02/03 | F37: Edge case | G37: Danh sách và tìm kiếm giao dịch | H37: Loại LC | I37: Kiểm tra danh sách giá trị lựa chọn của trường "Loại LC" (cập nhật SRS mới: 4 giá trị) | K37: Tìm kiếm-Thành công-Danh sách và tìm kiếm giao dịch-Kiểm tra giới hạn độ dài dữ liệu nhập trường "Tìm kiếm" (tối đa 50 ký tự)-- | L37: 1 Marker | M37: Step: Mở danh sách chọn của trường "Loại LC" và kiểm tra các giá trị hiển thị. | N37: Danh sách hiển thị đầy đủ, đúng 4 giá trị: Regular - UPAS - UPAS PLUS - Discounting (SRS mới bổ sung Discounting). | O37: Medium | S37: Not started
... A42: 89 | B42: FO | C42: S01 | D42: Danh sách & tìm kiếm giao dịch | E42: HF-01/02/03 | F42: Edge case | G42: Danh sách và tìm kiếm giao dịch | H42: Loại tiền LC | I42: Kiểm tra chọn giá trị hợp lệ cho trường "Loại tiền LC" | K42: Loại LC-Thành công-Danh sách và tìm kiếm giao dịch-Kiểm tra chọn giá trị hợp lệ cho trường "Loại LC"-- | L42: 1 Marker | M42: Step: Chọn 1 giá trị hợp lệ trong danh sách trường "Loại tiền LC" rồi Lưu/Gửi duyệt. | N42: Hệ thống chấp nhận giá trị đã chọn, cập nhật/hiển thị đúng theo lựa chọn và các trường phụ thuộc (nếu có) theo mô tả: Giá trị: Chọn đơn vị tiền tệ muốn tìm kiếm. | O42: Medium | S42: Not started
A43: 90 | B43: FO | C43: S01 | D43: Danh sách & tìm kiếm giao dịch | E43: HF-01/02/03 | F43: Edge case | G43: Danh sách và tìm kiếm giao dịch | H43: Trạng thái | I43: Kiểm tra chọn giá trị hợp lệ cho trường "Trạng thái" | K43: Tên khách hàng-Thành công-Danh sách và tìm kiếm giao dịch-Kiểm tra giới hạn độ dài dữ liệu nhập trường "Tên khách hàng" (tối đa 140 ký tự)-- | L43: 1 Marker | M43: Step: Chọn 1 giá trị hợp lệ trong danh sách trường "Trạng thái" rồi Lưu/Gửi duyệt. | N43: Hệ thống chấp nhận giá trị đã chọn, cập nhật/hiển thị đúng theo lựa chọn và các trường phụ thuộc (nếu có) theo mô tả: Giá trị: Tất cả Bản nháp Chờ duyệt Chờ duyệt cấp tiếp theo Chờ ký số pháp nhân Đã gửi ngân hàng Từ chối Ngân hàng từ chối Yêu cầu chỉnh sửa Ngân hàng yêu cầu bổ sung Đã hủy Hoàn thành Mặc định = “Tất | O43: Medium | P43: Cần xác nhận: ký số (USB token/HSM?) | S43: Not started
A44: 91 | B44: FO | C44: S01 | D44: Danh sách & tìm kiếm giao dịch | E44: HF-01/02/03 | F44: Edge case | G44: Danh sách và tìm kiếm giao dịch | H44: Áp dụng | I44: Kiểm tra chức năng nút "Áp dụng" | K44: Tên bên thụ hưởng-Thành công-Danh sách và tìm kiếm giao dịch-Kiểm tra giới hạn độ dài dữ liệu nhập trường "Tên bên thụ hưởng" (tối đa 140 ký tự)-- | L44: 1 Marker | M44: Step: Tại màn hình, nhấn nút "Áp dụng" và quan sát kết quả xử lý. | N44: Hệ thống thực hiện đúng chức năng của nút "Áp dụng" theo mô tả nghiệp vụ: Khi chọn, hệ thống tìm kiếm theo điều kiện đã nhập và trả về kết quả tìm kiếm | O44: Medium | S44: Not started
...
